WARNING 2018-11-15 16:22:51,987 base 152 Not Found: /
WARNING 2018-11-15 16:22:51,989 basehttp 124 "GET / HTTP/1.1" 404 2104
WARNING 2018-11-15 16:22:52,973 base 152 Not Found: /favicon.ico
WARNING 2018-11-15 16:22:52,974 basehttp 124 "GET /favicon.ico HTTP/1.1" 404 2155
WARNING 2018-11-15 16:23:23,574 base 152 Not Found: /sms_codes
WARNING 2018-11-15 16:23:23,577 basehttp 124 "GET /sms_codes HTTP/1.1" 404 2149
INFO 2018-11-15 16:25:04,457 basehttp 124 "GET /sms_codes/15812341234 HTTP/1.1" 301 0
WARNING 2018-11-15 16:26:55,828 base 152 Not Found: /sms_codes
WARNING 2018-11-15 16:26:55,831 basehttp 124 "GET /sms_codes HTTP/1.1" 404 2149
WARNING 2018-11-15 16:26:56,877 base 152 Not Found: /sms_codes
WARNING 2018-11-15 16:26:56,878 basehttp 124 "GET /sms_codes HTTP/1.1" 404 2149
WARNING 2018-11-15 16:26:57,696 base 152 Not Found: /sms_codes
WARNING 2018-11-15 16:26:57,697 basehttp 124 "GET /sms_codes HTTP/1.1" 404 2149
WARNING 2018-11-15 16:27:36,459 base 152 Not Found: /
WARNING 2018-11-15 16:27:36,466 basehttp 124 "GET / HTTP/1.1" 404 2104
ERROR 2018-11-15 16:41:35,131 exception 135 Internal Server Error: /sms_codes/15812341234/
Traceback (most recent call last):
  File "/Users/yinshuanglong/dj/lib/python3.6/site-packages/redis/connection.py", line 484, in connect
    sock = self._connect()
  File "/Users/yinshuanglong/dj/lib/python3.6/site-packages/redis/connection.py", line 541, in _connect
    raise err
  File "/Users/yinshuanglong/dj/lib/python3.6/site-packages/redis/connection.py", line 529, in _connect
    sock.connect(socket_address)
TimeoutError: [Errno 60] Operation timed out

During handling of the above exception, another exception occurred:

Traceback (most recent call last):
  File "/Users/yinshuanglong/dj/lib/python3.6/site-packages/redis/client.py", line 667, in execute_command
    connection.send_command(*args)
  File "/Users/yinshuanglong/dj/lib/python3.6/site-packages/redis/connection.py", line 610, in send_command
    self.send_packed_command(self.pack_command(*args))
  File "/Users/yinshuanglong/dj/lib/python3.6/site-packages/redis/connection.py", line 585, in send_packed_command
    self.connect()
  File "/Users/yinshuanglong/dj/lib/python3.6/site-packages/redis/connection.py", line 489, in connect
    raise ConnectionError(self._error_message(e))
redis.exceptions.ConnectionError: Error 60 connecting to 10.211.55.5:6379. Operation timed out.

During handling of the above exception, another exception occurred:

Traceback (most recent call last):
  File "/Users/yinshuanglong/dj/lib/python3.6/site-packages/redis/connection.py", line 484, in connect
    sock = self._connect()
  File "/Users/yinshuanglong/dj/lib/python3.6/site-packages/redis/connection.py", line 541, in _connect
    raise err
  File "/Users/yinshuanglong/dj/lib/python3.6/site-packages/redis/connection.py", line 529, in _connect
    sock.connect(socket_address)
TimeoutError: [Errno 60] Operation timed out

During handling of the above exception, another exception occurred:

Traceback (most recent call last):
  File "/Users/yinshuanglong/dj/lib/python3.6/site-packages/rest_framework/views.py", line 492, in dispatch
    response = handler(request, *args, **kwargs)
  File "/Users/yinshuanglong/Desktop/mido/mido_mall/mido_mall/apps/verifications/views.py", line 26, in get
    send_flag=redis_conn.get('smsflag_%s'%mobile)
  File "/Users/yinshuanglong/dj/lib/python3.6/site-packages/redis/client.py", line 976, in get
    return self.execute_command('GET', name)
  File "/Users/yinshuanglong/dj/lib/python3.6/site-packages/redis/client.py", line 673, in execute_command
    connection.send_command(*args)
  File "/Users/yinshuanglong/dj/lib/python3.6/site-packages/redis/connection.py", line 610, in send_command
    self.send_packed_command(self.pack_command(*args))
  File "/Users/yinshuanglong/dj/lib/python3.6/site-packages/redis/connection.py", line 585, in send_packed_command
    self.connect()
  File "/Users/yinshuanglong/dj/lib/python3.6/site-packages/redis/connection.py", line 489, in connect
    raise ConnectionError(self._error_message(e))
redis.exceptions.ConnectionError: Error 60 connecting to 10.211.55.5:6379. Operation timed out.

During handling of the above exception, another exception occurred:

Traceback (most recent call last):
  File "/Users/yinshuanglong/dj/lib/python3.6/site-packages/django/core/handlers/exception.py", line 41, in inner
    response = get_response(request)
  File "/Users/yinshuanglong/dj/lib/python3.6/site-packages/django/core/handlers/base.py", line 187, in _get_response
    response = self.process_exception_by_middleware(e, request)
  File "/Users/yinshuanglong/dj/lib/python3.6/site-packages/django/core/handlers/base.py", line 185, in _get_response
    response = wrapped_callback(request, *callback_args, **callback_kwargs)
  File "/Users/yinshuanglong/dj/lib/python3.6/site-packages/django/views/decorators/csrf.py", line 58, in wrapped_view
    return view_func(*args, **kwargs)
  File "/Users/yinshuanglong/dj/lib/python3.6/site-packages/django/views/generic/base.py", line 68, in view
    return self.dispatch(request, *args, **kwargs)
  File "/Users/yinshuanglong/dj/lib/python3.6/site-packages/rest_framework/views.py", line 495, in dispatch
    response = self.handle_exception(exc)
  File "/Users/yinshuanglong/dj/lib/python3.6/site-packages/rest_framework/views.py", line 452, in handle_exception
    response = exception_handler(exc, context)
  File "/Users/yinshuanglong/Desktop/mido/mido_mall/mido_mall/utils/exceptions.py", line 27, in exception_handler
    if isinstance(exc, DatabaseError) or isinstance(RedisError):
TypeError: isinstance expected 2 arguments, got 1
ERROR 2018-11-15 16:41:35,335 basehttp 124 "GET /sms_codes/15812341234/ HTTP/1.1" 500 152869
ERROR 2018-11-15 16:42:50,575 exception 135 Internal Server Error: /sms_codes/15812341234/
Traceback (most recent call last):
  File "/Users/yinshuanglong/dj/lib/python3.6/site-packages/redis/connection.py", line 484, in connect
    sock = self._connect()
  File "/Users/yinshuanglong/dj/lib/python3.6/site-packages/redis/connection.py", line 541, in _connect
    raise err
  File "/Users/yinshuanglong/dj/lib/python3.6/site-packages/redis/connection.py", line 529, in _connect
    sock.connect(socket_address)
TimeoutError: [Errno 60] Operation timed out

During handling of the above exception, another exception occurred:

Traceback (most recent call last):
  File "/Users/yinshuanglong/dj/lib/python3.6/site-packages/redis/client.py", line 667, in execute_command
    connection.send_command(*args)
  File "/Users/yinshuanglong/dj/lib/python3.6/site-packages/redis/connection.py", line 610, in send_command
    self.send_packed_command(self.pack_command(*args))
  File "/Users/yinshuanglong/dj/lib/python3.6/site-packages/redis/connection.py", line 585, in send_packed_command
    self.connect()
  File "/Users/yinshuanglong/dj/lib/python3.6/site-packages/redis/connection.py", line 489, in connect
    raise ConnectionError(self._error_message(e))
redis.exceptions.ConnectionError: Error 60 connecting to 10.211.55.5:6379. Operation timed out.

During handling of the above exception, another exception occurred:

Traceback (most recent call last):
  File "/Users/yinshuanglong/dj/lib/python3.6/site-packages/redis/connection.py", line 484, in connect
    sock = self._connect()
  File "/Users/yinshuanglong/dj/lib/python3.6/site-packages/redis/connection.py", line 541, in _connect
    raise err
  File "/Users/yinshuanglong/dj/lib/python3.6/site-packages/redis/connection.py", line 529, in _connect
    sock.connect(socket_address)
TimeoutError: [Errno 60] Operation timed out

During handling of the above exception, another exception occurred:

Traceback (most recent call last):
  File "/Users/yinshuanglong/dj/lib/python3.6/site-packages/rest_framework/views.py", line 492, in dispatch
    response = handler(request, *args, **kwargs)
  File "/Users/yinshuanglong/Desktop/mido/mido_mall/mido_mall/apps/verifications/views.py", line 26, in get
    send_flag=redis_conn.get('smsflag_%s'%mobile)
  File "/Users/yinshuanglong/dj/lib/python3.6/site-packages/redis/client.py", line 976, in get
    return self.execute_command('GET', name)
  File "/Users/yinshuanglong/dj/lib/python3.6/site-packages/redis/client.py", line 673, in execute_command
    connection.send_command(*args)
  File "/Users/yinshuanglong/dj/lib/python3.6/site-packages/redis/connection.py", line 610, in send_command
    self.send_packed_command(self.pack_command(*args))
  File "/Users/yinshuanglong/dj/lib/python3.6/site-packages/redis/connection.py", line 585, in send_packed_command
    self.connect()
  File "/Users/yinshuanglong/dj/lib/python3.6/site-packages/redis/connection.py", line 489, in connect
    raise ConnectionError(self._error_message(e))
redis.exceptions.ConnectionError: Error 60 connecting to 10.211.55.5:6379. Operation timed out.

During handling of the above exception, another exception occurred:

Traceback (most recent call last):
  File "/Users/yinshuanglong/dj/lib/python3.6/site-packages/django/core/handlers/exception.py", line 41, in inner
    response = get_response(request)
  File "/Users/yinshuanglong/dj/lib/python3.6/site-packages/django/core/handlers/base.py", line 187, in _get_response
    response = self.process_exception_by_middleware(e, request)
  File "/Users/yinshuanglong/dj/lib/python3.6/site-packages/django/core/handlers/base.py", line 185, in _get_response
    response = wrapped_callback(request, *callback_args, **callback_kwargs)
  File "/Users/yinshuanglong/dj/lib/python3.6/site-packages/django/views/decorators/csrf.py", line 58, in wrapped_view
    return view_func(*args, **kwargs)
  File "/Users/yinshuanglong/dj/lib/python3.6/site-packages/django/views/generic/base.py", line 68, in view
    return self.dispatch(request, *args, **kwargs)
  File "/Users/yinshuanglong/dj/lib/python3.6/site-packages/rest_framework/views.py", line 495, in dispatch
    response = self.handle_exception(exc)
  File "/Users/yinshuanglong/dj/lib/python3.6/site-packages/rest_framework/views.py", line 452, in handle_exception
    response = exception_handler(exc, context)
  File "/Users/yinshuanglong/Desktop/mido/mido_mall/mido_mall/utils/exceptions.py", line 27, in exception_handler
    if isinstance(exc, DatabaseError) or isinstance(RedisError):
TypeError: isinstance expected 2 arguments, got 1
ERROR 2018-11-15 16:42:50,716 basehttp 124 "GET /sms_codes/15812341234/ HTTP/1.1" 500 152870
ERROR 2018-11-15 16:59:01,101 exception 135 Internal Server Error: /sms_codes/15812341234/
Traceback (most recent call last):
  File "/Users/yinshuanglong/dj/lib/python3.6/site-packages/redis/connection.py", line 484, in connect
    sock = self._connect()
  File "/Users/yinshuanglong/dj/lib/python3.6/site-packages/redis/connection.py", line 541, in _connect
    raise err
  File "/Users/yinshuanglong/dj/lib/python3.6/site-packages/redis/connection.py", line 529, in _connect
    sock.connect(socket_address)
TimeoutError: [Errno 60] Operation timed out

During handling of the above exception, another exception occurred:

Traceback (most recent call last):
  File "/Users/yinshuanglong/dj/lib/python3.6/site-packages/redis/client.py", line 667, in execute_command
    connection.send_command(*args)
  File "/Users/yinshuanglong/dj/lib/python3.6/site-packages/redis/connection.py", line 610, in send_command
    self.send_packed_command(self.pack_command(*args))
  File "/Users/yinshuanglong/dj/lib/python3.6/site-packages/redis/connection.py", line 585, in send_packed_command
    self.connect()
  File "/Users/yinshuanglong/dj/lib/python3.6/site-packages/redis/connection.py", line 489, in connect
    raise ConnectionError(self._error_message(e))
redis.exceptions.ConnectionError: Error 60 connecting to 10.211.55.5:6379. Operation timed out.

During handling of the above exception, another exception occurred:

Traceback (most recent call last):
  File "/Users/yinshuanglong/dj/lib/python3.6/site-packages/redis/connection.py", line 484, in connect
    sock = self._connect()
  File "/Users/yinshuanglong/dj/lib/python3.6/site-packages/redis/connection.py", line 541, in _connect
    raise err
  File "/Users/yinshuanglong/dj/lib/python3.6/site-packages/redis/connection.py", line 529, in _connect
    sock.connect(socket_address)
TimeoutError: [Errno 60] Operation timed out

During handling of the above exception, another exception occurred:

Traceback (most recent call last):
  File "/Users/yinshuanglong/dj/lib/python3.6/site-packages/rest_framework/views.py", line 492, in dispatch
    response = handler(request, *args, **kwargs)
  File "/Users/yinshuanglong/Desktop/mido/mido_mall/mido_mall/apps/verifications/views.py", line 29, in get
    send_flag=redis_conn.get('smsflag_%s'% mobile)
  File "/Users/yinshuanglong/dj/lib/python3.6/site-packages/redis/client.py", line 976, in get
    return self.execute_command('GET', name)
  File "/Users/yinshuanglong/dj/lib/python3.6/site-packages/redis/client.py", line 673, in execute_command
    connection.send_command(*args)
  File "/Users/yinshuanglong/dj/lib/python3.6/site-packages/redis/connection.py", line 610, in send_command
    self.send_packed_command(self.pack_command(*args))
  File "/Users/yinshuanglong/dj/lib/python3.6/site-packages/redis/connection.py", line 585, in send_packed_command
    self.connect()
  File "/Users/yinshuanglong/dj/lib/python3.6/site-packages/redis/connection.py", line 489, in connect
    raise ConnectionError(self._error_message(e))
redis.exceptions.ConnectionError: Error 60 connecting to 10.211.55.5:6379. Operation timed out.

During handling of the above exception, another exception occurred:

Traceback (most recent call last):
  File "/Users/yinshuanglong/dj/lib/python3.6/site-packages/django/core/handlers/exception.py", line 41, in inner
    response = get_response(request)
  File "/Users/yinshuanglong/dj/lib/python3.6/site-packages/django/core/handlers/base.py", line 187, in _get_response
    response = self.process_exception_by_middleware(e, request)
  File "/Users/yinshuanglong/dj/lib/python3.6/site-packages/django/core/handlers/base.py", line 185, in _get_response
    response = wrapped_callback(request, *callback_args, **callback_kwargs)
  File "/Users/yinshuanglong/dj/lib/python3.6/site-packages/django/views/decorators/csrf.py", line 58, in wrapped_view
    return view_func(*args, **kwargs)
  File "/Users/yinshuanglong/dj/lib/python3.6/site-packages/django/views/generic/base.py", line 68, in view
    return self.dispatch(request, *args, **kwargs)
  File "/Users/yinshuanglong/dj/lib/python3.6/site-packages/rest_framework/views.py", line 495, in dispatch
    response = self.handle_exception(exc)
  File "/Users/yinshuanglong/dj/lib/python3.6/site-packages/rest_framework/views.py", line 452, in handle_exception
    response = exception_handler(exc, context)
  File "/Users/yinshuanglong/Desktop/mido/mido_mall/mido_mall/utils/exceptions.py", line 27, in exception_handler
    if isinstance(exc, DatabaseError) or isinstance(RedisError):
TypeError: isinstance expected 2 arguments, got 1
ERROR 2018-11-15 16:59:01,349 basehttp 124 "GET /sms_codes/15812341234/ HTTP/1.1" 500 152783
ERROR 2018-11-15 17:06:42,408 exception 135 Internal Server Error: /sms_codes/15812341234/
Traceback (most recent call last):
  File "/Users/yinshuanglong/dj/lib/python3.6/site-packages/redis/connection.py", line 484, in connect
    sock = self._connect()
  File "/Users/yinshuanglong/dj/lib/python3.6/site-packages/redis/connection.py", line 541, in _connect
    raise err
  File "/Users/yinshuanglong/dj/lib/python3.6/site-packages/redis/connection.py", line 529, in _connect
    sock.connect(socket_address)
TimeoutError: [Errno 60] Operation timed out

During handling of the above exception, another exception occurred:

Traceback (most recent call last):
  File "/Users/yinshuanglong/dj/lib/python3.6/site-packages/redis/client.py", line 667, in execute_command
    connection.send_command(*args)
  File "/Users/yinshuanglong/dj/lib/python3.6/site-packages/redis/connection.py", line 610, in send_command
    self.send_packed_command(self.pack_command(*args))
  File "/Users/yinshuanglong/dj/lib/python3.6/site-packages/redis/connection.py", line 585, in send_packed_command
    self.connect()
  File "/Users/yinshuanglong/dj/lib/python3.6/site-packages/redis/connection.py", line 489, in connect
    raise ConnectionError(self._error_message(e))
redis.exceptions.ConnectionError: Error 60 connecting to 10.211.55.5:6379. Operation timed out.

During handling of the above exception, another exception occurred:

Traceback (most recent call last):
  File "/Users/yinshuanglong/dj/lib/python3.6/site-packages/redis/connection.py", line 484, in connect
    sock = self._connect()
  File "/Users/yinshuanglong/dj/lib/python3.6/site-packages/redis/connection.py", line 541, in _connect
    raise err
  File "/Users/yinshuanglong/dj/lib/python3.6/site-packages/redis/connection.py", line 529, in _connect
    sock.connect(socket_address)
TimeoutError: [Errno 60] Operation timed out

During handling of the above exception, another exception occurred:

Traceback (most recent call last):
  File "/Users/yinshuanglong/dj/lib/python3.6/site-packages/rest_framework/views.py", line 492, in dispatch
    response = handler(request, *args, **kwargs)
  File "/Users/yinshuanglong/Desktop/mido/mido_mall/mido_mall/apps/verifications/views.py", line 29, in get
    send_flag=redis_conn.get('smsflag_%s'% mobile)
  File "/Users/yinshuanglong/dj/lib/python3.6/site-packages/redis/client.py", line 976, in get
    return self.execute_command('GET', name)
  File "/Users/yinshuanglong/dj/lib/python3.6/site-packages/redis/client.py", line 673, in execute_command
    connection.send_command(*args)
  File "/Users/yinshuanglong/dj/lib/python3.6/site-packages/redis/connection.py", line 610, in send_command
    self.send_packed_command(self.pack_command(*args))
  File "/Users/yinshuanglong/dj/lib/python3.6/site-packages/redis/connection.py", line 585, in send_packed_command
    self.connect()
  File "/Users/yinshuanglong/dj/lib/python3.6/site-packages/redis/connection.py", line 489, in connect
    raise ConnectionError(self._error_message(e))
redis.exceptions.ConnectionError: Error 60 connecting to 10.211.55.5:6379. Operation timed out.

During handling of the above exception, another exception occurred:

Traceback (most recent call last):
  File "/Users/yinshuanglong/dj/lib/python3.6/site-packages/django/core/handlers/exception.py", line 41, in inner
    response = get_response(request)
  File "/Users/yinshuanglong/dj/lib/python3.6/site-packages/django/core/handlers/base.py", line 187, in _get_response
    response = self.process_exception_by_middleware(e, request)
  File "/Users/yinshuanglong/dj/lib/python3.6/site-packages/django/core/handlers/base.py", line 185, in _get_response
    response = wrapped_callback(request, *callback_args, **callback_kwargs)
  File "/Users/yinshuanglong/dj/lib/python3.6/site-packages/django/views/decorators/csrf.py", line 58, in wrapped_view
    return view_func(*args, **kwargs)
  File "/Users/yinshuanglong/dj/lib/python3.6/site-packages/django/views/generic/base.py", line 68, in view
    return self.dispatch(request, *args, **kwargs)
  File "/Users/yinshuanglong/dj/lib/python3.6/site-packages/rest_framework/views.py", line 495, in dispatch
    response = self.handle_exception(exc)
  File "/Users/yinshuanglong/dj/lib/python3.6/site-packages/rest_framework/views.py", line 452, in handle_exception
    response = exception_handler(exc, context)
  File "/Users/yinshuanglong/Desktop/mido/mido_mall/mido_mall/utils/exceptions.py", line 27, in exception_handler
    if isinstance(exc, DatabaseError) or isinstance(RedisError):
TypeError: isinstance expected 2 arguments, got 1
ERROR 2018-11-15 17:06:42,712 basehttp 124 "GET /sms_codes/15812341234/ HTTP/1.1" 500 152783
ERROR 2018-11-15 17:11:56,877 exception 135 Internal Server Error: /sms_codes/15812341234/
Traceback (most recent call last):
  File "/Users/yinshuanglong/dj/lib/python3.6/site-packages/redis/connection.py", line 484, in connect
    sock = self._connect()
  File "/Users/yinshuanglong/dj/lib/python3.6/site-packages/redis/connection.py", line 541, in _connect
    raise err
  File "/Users/yinshuanglong/dj/lib/python3.6/site-packages/redis/connection.py", line 529, in _connect
    sock.connect(socket_address)
TimeoutError: [Errno 60] Operation timed out

During handling of the above exception, another exception occurred:

Traceback (most recent call last):
  File "/Users/yinshuanglong/dj/lib/python3.6/site-packages/redis/client.py", line 667, in execute_command
    connection.send_command(*args)
  File "/Users/yinshuanglong/dj/lib/python3.6/site-packages/redis/connection.py", line 610, in send_command
    self.send_packed_command(self.pack_command(*args))
  File "/Users/yinshuanglong/dj/lib/python3.6/site-packages/redis/connection.py", line 585, in send_packed_command
    self.connect()
  File "/Users/yinshuanglong/dj/lib/python3.6/site-packages/redis/connection.py", line 489, in connect
    raise ConnectionError(self._error_message(e))
redis.exceptions.ConnectionError: Error 60 connecting to 10.211.55.5:6379. Operation timed out.

During handling of the above exception, another exception occurred:

Traceback (most recent call last):
  File "/Users/yinshuanglong/dj/lib/python3.6/site-packages/redis/connection.py", line 484, in connect
    sock = self._connect()
  File "/Users/yinshuanglong/dj/lib/python3.6/site-packages/redis/connection.py", line 541, in _connect
    raise err
  File "/Users/yinshuanglong/dj/lib/python3.6/site-packages/redis/connection.py", line 529, in _connect
    sock.connect(socket_address)
TimeoutError: [Errno 60] Operation timed out

During handling of the above exception, another exception occurred:

Traceback (most recent call last):
  File "/Users/yinshuanglong/dj/lib/python3.6/site-packages/rest_framework/views.py", line 492, in dispatch
    response = handler(request, *args, **kwargs)
  File "/Users/yinshuanglong/Desktop/mido/mido_mall/mido_mall/apps/verifications/views.py", line 29, in get
    send_flag=redis_conn.get('smsflag_%s'% mobile)
  File "/Users/yinshuanglong/dj/lib/python3.6/site-packages/redis/client.py", line 976, in get
    return self.execute_command('GET', name)
  File "/Users/yinshuanglong/dj/lib/python3.6/site-packages/redis/client.py", line 673, in execute_command
    connection.send_command(*args)
  File "/Users/yinshuanglong/dj/lib/python3.6/site-packages/redis/connection.py", line 610, in send_command
    self.send_packed_command(self.pack_command(*args))
  File "/Users/yinshuanglong/dj/lib/python3.6/site-packages/redis/connection.py", line 585, in send_packed_command
    self.connect()
  File "/Users/yinshuanglong/dj/lib/python3.6/site-packages/redis/connection.py", line 489, in connect
    raise ConnectionError(self._error_message(e))
redis.exceptions.ConnectionError: Error 60 connecting to 10.211.55.5:6379. Operation timed out.

During handling of the above exception, another exception occurred:

Traceback (most recent call last):
  File "/Users/yinshuanglong/dj/lib/python3.6/site-packages/django/core/handlers/exception.py", line 41, in inner
    response = get_response(request)
  File "/Users/yinshuanglong/dj/lib/python3.6/site-packages/django/core/handlers/base.py", line 187, in _get_response
    response = self.process_exception_by_middleware(e, request)
  File "/Users/yinshuanglong/dj/lib/python3.6/site-packages/django/core/handlers/base.py", line 185, in _get_response
    response = wrapped_callback(request, *callback_args, **callback_kwargs)
  File "/Users/yinshuanglong/dj/lib/python3.6/site-packages/django/views/decorators/csrf.py", line 58, in wrapped_view
    return view_func(*args, **kwargs)
  File "/Users/yinshuanglong/dj/lib/python3.6/site-packages/django/views/generic/base.py", line 68, in view
    return self.dispatch(request, *args, **kwargs)
  File "/Users/yinshuanglong/dj/lib/python3.6/site-packages/rest_framework/views.py", line 495, in dispatch
    response = self.handle_exception(exc)
  File "/Users/yinshuanglong/dj/lib/python3.6/site-packages/rest_framework/views.py", line 452, in handle_exception
    response = exception_handler(exc, context)
  File "/Users/yinshuanglong/Desktop/mido/mido_mall/mido_mall/utils/exceptions.py", line 27, in exception_handler
    if isinstance(exc, DatabaseError) or isinstance(RedisError):
TypeError: isinstance expected 2 arguments, got 1
ERROR 2018-11-15 17:11:57,042 basehttp 124 "GET /sms_codes/15812341234/ HTTP/1.1" 500 152783
ERROR 2018-11-15 17:18:29,674 exception 135 Internal Server Error: /sms_codes/15812341234/
Traceback (most recent call last):
  File "/Users/yinshuanglong/dj/lib/python3.6/site-packages/redis/connection.py", line 484, in connect
    sock = self._connect()
  File "/Users/yinshuanglong/dj/lib/python3.6/site-packages/redis/connection.py", line 541, in _connect
    raise err
  File "/Users/yinshuanglong/dj/lib/python3.6/site-packages/redis/connection.py", line 529, in _connect
    sock.connect(socket_address)
TimeoutError: [Errno 60] Operation timed out

During handling of the above exception, another exception occurred:

Traceback (most recent call last):
  File "/Users/yinshuanglong/dj/lib/python3.6/site-packages/redis/client.py", line 667, in execute_command
    connection.send_command(*args)
  File "/Users/yinshuanglong/dj/lib/python3.6/site-packages/redis/connection.py", line 610, in send_command
    self.send_packed_command(self.pack_command(*args))
  File "/Users/yinshuanglong/dj/lib/python3.6/site-packages/redis/connection.py", line 585, in send_packed_command
    self.connect()
  File "/Users/yinshuanglong/dj/lib/python3.6/site-packages/redis/connection.py", line 489, in connect
    raise ConnectionError(self._error_message(e))
redis.exceptions.ConnectionError: Error 60 connecting to 10.211.55.5:6379. Operation timed out.

During handling of the above exception, another exception occurred:

Traceback (most recent call last):
  File "/Users/yinshuanglong/dj/lib/python3.6/site-packages/redis/connection.py", line 484, in connect
    sock = self._connect()
  File "/Users/yinshuanglong/dj/lib/python3.6/site-packages/redis/connection.py", line 541, in _connect
    raise err
  File "/Users/yinshuanglong/dj/lib/python3.6/site-packages/redis/connection.py", line 529, in _connect
    sock.connect(socket_address)
TimeoutError: [Errno 60] Operation timed out

During handling of the above exception, another exception occurred:

Traceback (most recent call last):
  File "/Users/yinshuanglong/dj/lib/python3.6/site-packages/rest_framework/views.py", line 492, in dispatch
    response = handler(request, *args, **kwargs)
  File "/Users/yinshuanglong/Desktop/mido/mido_mall/mido_mall/apps/verifications/views.py", line 29, in get
    send_flag=redis_conn.get('smsflag_%s'% mobile)
  File "/Users/yinshuanglong/dj/lib/python3.6/site-packages/redis/client.py", line 976, in get
    return self.execute_command('GET', name)
  File "/Users/yinshuanglong/dj/lib/python3.6/site-packages/redis/client.py", line 673, in execute_command
    connection.send_command(*args)
  File "/Users/yinshuanglong/dj/lib/python3.6/site-packages/redis/connection.py", line 610, in send_command
    self.send_packed_command(self.pack_command(*args))
  File "/Users/yinshuanglong/dj/lib/python3.6/site-packages/redis/connection.py", line 585, in send_packed_command
    self.connect()
  File "/Users/yinshuanglong/dj/lib/python3.6/site-packages/redis/connection.py", line 489, in connect
    raise ConnectionError(self._error_message(e))
redis.exceptions.ConnectionError: Error 60 connecting to 10.211.55.5:6379. Operation timed out.

During handling of the above exception, another exception occurred:

Traceback (most recent call last):
  File "/Users/yinshuanglong/dj/lib/python3.6/site-packages/django/core/handlers/exception.py", line 41, in inner
    response = get_response(request)
  File "/Users/yinshuanglong/dj/lib/python3.6/site-packages/django/core/handlers/base.py", line 187, in _get_response
    response = self.process_exception_by_middleware(e, request)
  File "/Users/yinshuanglong/dj/lib/python3.6/site-packages/django/core/handlers/base.py", line 185, in _get_response
    response = wrapped_callback(request, *callback_args, **callback_kwargs)
  File "/Users/yinshuanglong/dj/lib/python3.6/site-packages/django/views/decorators/csrf.py", line 58, in wrapped_view
    return view_func(*args, **kwargs)
  File "/Users/yinshuanglong/dj/lib/python3.6/site-packages/django/views/generic/base.py", line 68, in view
    return self.dispatch(request, *args, **kwargs)
  File "/Users/yinshuanglong/dj/lib/python3.6/site-packages/rest_framework/views.py", line 495, in dispatch
    response = self.handle_exception(exc)
  File "/Users/yinshuanglong/dj/lib/python3.6/site-packages/rest_framework/views.py", line 452, in handle_exception
    response = exception_handler(exc, context)
  File "/Users/yinshuanglong/Desktop/mido/mido_mall/mido_mall/utils/exceptions.py", line 27, in exception_handler
    if isinstance(exc, DatabaseError) or isinstance(RedisError):
TypeError: isinstance expected 2 arguments, got 1
ERROR 2018-11-15 17:18:29,853 basehttp 124 "GET /sms_codes/15812341234/ HTTP/1.1" 500 152783
ERROR 2018-11-15 17:20:39,562 exception 135 Internal Server Error: /sms_codes/15812341234/
Traceback (most recent call last):
  File "/Users/yinshuanglong/dj/lib/python3.6/site-packages/redis/connection.py", line 484, in connect
    sock = self._connect()
  File "/Users/yinshuanglong/dj/lib/python3.6/site-packages/redis/connection.py", line 541, in _connect
    raise err
  File "/Users/yinshuanglong/dj/lib/python3.6/site-packages/redis/connection.py", line 529, in _connect
    sock.connect(socket_address)
TimeoutError: [Errno 60] Operation timed out

During handling of the above exception, another exception occurred:

Traceback (most recent call last):
  File "/Users/yinshuanglong/dj/lib/python3.6/site-packages/redis/client.py", line 667, in execute_command
    connection.send_command(*args)
  File "/Users/yinshuanglong/dj/lib/python3.6/site-packages/redis/connection.py", line 610, in send_command
    self.send_packed_command(self.pack_command(*args))
  File "/Users/yinshuanglong/dj/lib/python3.6/site-packages/redis/connection.py", line 585, in send_packed_command
    self.connect()
  File "/Users/yinshuanglong/dj/lib/python3.6/site-packages/redis/connection.py", line 489, in connect
    raise ConnectionError(self._error_message(e))
redis.exceptions.ConnectionError: Error 60 connecting to 10.211.55.5:6379. Operation timed out.

During handling of the above exception, another exception occurred:

Traceback (most recent call last):
  File "/Users/yinshuanglong/dj/lib/python3.6/site-packages/redis/connection.py", line 484, in connect
    sock = self._connect()
  File "/Users/yinshuanglong/dj/lib/python3.6/site-packages/redis/connection.py", line 541, in _connect
    raise err
  File "/Users/yinshuanglong/dj/lib/python3.6/site-packages/redis/connection.py", line 529, in _connect
    sock.connect(socket_address)
TimeoutError: [Errno 60] Operation timed out

During handling of the above exception, another exception occurred:

Traceback (most recent call last):
  File "/Users/yinshuanglong/dj/lib/python3.6/site-packages/rest_framework/views.py", line 492, in dispatch
    response = handler(request, *args, **kwargs)
  File "/Users/yinshuanglong/Desktop/mido/mido_mall/mido_mall/apps/verifications/views.py", line 29, in get
    send_flag=redis_conn.get('smsflag_%s'% mobile)
  File "/Users/yinshuanglong/dj/lib/python3.6/site-packages/redis/client.py", line 976, in get
    return self.execute_command('GET', name)
  File "/Users/yinshuanglong/dj/lib/python3.6/site-packages/redis/client.py", line 673, in execute_command
    connection.send_command(*args)
  File "/Users/yinshuanglong/dj/lib/python3.6/site-packages/redis/connection.py", line 610, in send_command
    self.send_packed_command(self.pack_command(*args))
  File "/Users/yinshuanglong/dj/lib/python3.6/site-packages/redis/connection.py", line 585, in send_packed_command
    self.connect()
  File "/Users/yinshuanglong/dj/lib/python3.6/site-packages/redis/connection.py", line 489, in connect
    raise ConnectionError(self._error_message(e))
redis.exceptions.ConnectionError: Error 60 connecting to 10.211.55.5:6379. Operation timed out.

During handling of the above exception, another exception occurred:

Traceback (most recent call last):
  File "/Users/yinshuanglong/dj/lib/python3.6/site-packages/django/core/handlers/exception.py", line 41, in inner
    response = get_response(request)
  File "/Users/yinshuanglong/dj/lib/python3.6/site-packages/django/core/handlers/base.py", line 187, in _get_response
    response = self.process_exception_by_middleware(e, request)
  File "/Users/yinshuanglong/dj/lib/python3.6/site-packages/django/core/handlers/base.py", line 185, in _get_response
    response = wrapped_callback(request, *callback_args, **callback_kwargs)
  File "/Users/yinshuanglong/dj/lib/python3.6/site-packages/django/views/decorators/csrf.py", line 58, in wrapped_view
    return view_func(*args, **kwargs)
  File "/Users/yinshuanglong/dj/lib/python3.6/site-packages/django/views/generic/base.py", line 68, in view
    return self.dispatch(request, *args, **kwargs)
  File "/Users/yinshuanglong/dj/lib/python3.6/site-packages/rest_framework/views.py", line 495, in dispatch
    response = self.handle_exception(exc)
  File "/Users/yinshuanglong/dj/lib/python3.6/site-packages/rest_framework/views.py", line 452, in handle_exception
    response = exception_handler(exc, context)
  File "/Users/yinshuanglong/Desktop/mido/mido_mall/mido_mall/utils/exceptions.py", line 27, in exception_handler
    if isinstance(exc, DatabaseError) or isinstance(RedisError):
TypeError: isinstance expected 2 arguments, got 1
ERROR 2018-11-15 17:20:39,696 basehttp 124 "GET /sms_codes/15812341234/ HTTP/1.1" 500 152784
ERROR 2018-11-15 17:29:59,241 exception 135 Internal Server Error: /sms_codes/15812341234/
Traceback (most recent call last):
  File "/Users/yinshuanglong/dj/lib/python3.6/site-packages/redis/connection.py", line 484, in connect
    sock = self._connect()
  File "/Users/yinshuanglong/dj/lib/python3.6/site-packages/redis/connection.py", line 541, in _connect
    raise err
  File "/Users/yinshuanglong/dj/lib/python3.6/site-packages/redis/connection.py", line 529, in _connect
    sock.connect(socket_address)
TimeoutError: [Errno 60] Operation timed out

During handling of the above exception, another exception occurred:

Traceback (most recent call last):
  File "/Users/yinshuanglong/dj/lib/python3.6/site-packages/redis/client.py", line 667, in execute_command
    connection.send_command(*args)
  File "/Users/yinshuanglong/dj/lib/python3.6/site-packages/redis/connection.py", line 610, in send_command
    self.send_packed_command(self.pack_command(*args))
  File "/Users/yinshuanglong/dj/lib/python3.6/site-packages/redis/connection.py", line 585, in send_packed_command
    self.connect()
  File "/Users/yinshuanglong/dj/lib/python3.6/site-packages/redis/connection.py", line 489, in connect
    raise ConnectionError(self._error_message(e))
redis.exceptions.ConnectionError: Error 60 connecting to 10.211.55.5:6379. Operation timed out.

During handling of the above exception, another exception occurred:

Traceback (most recent call last):
  File "/Users/yinshuanglong/dj/lib/python3.6/site-packages/redis/connection.py", line 484, in connect
    sock = self._connect()
  File "/Users/yinshuanglong/dj/lib/python3.6/site-packages/redis/connection.py", line 541, in _connect
    raise err
  File "/Users/yinshuanglong/dj/lib/python3.6/site-packages/redis/connection.py", line 529, in _connect
    sock.connect(socket_address)
TimeoutError: [Errno 60] Operation timed out

During handling of the above exception, another exception occurred:

Traceback (most recent call last):
  File "/Users/yinshuanglong/dj/lib/python3.6/site-packages/rest_framework/views.py", line 492, in dispatch
    response = handler(request, *args, **kwargs)
  File "/Users/yinshuanglong/Desktop/mido/mido_mall/mido_mall/apps/verifications/views.py", line 29, in get
    send_flag=redis_conn.get('smsflag_%s'% mobile)
  File "/Users/yinshuanglong/dj/lib/python3.6/site-packages/redis/client.py", line 976, in get
    return self.execute_command('GET', name)
  File "/Users/yinshuanglong/dj/lib/python3.6/site-packages/redis/client.py", line 673, in execute_command
    connection.send_command(*args)
  File "/Users/yinshuanglong/dj/lib/python3.6/site-packages/redis/connection.py", line 610, in send_command
    self.send_packed_command(self.pack_command(*args))
  File "/Users/yinshuanglong/dj/lib/python3.6/site-packages/redis/connection.py", line 585, in send_packed_command
    self.connect()
  File "/Users/yinshuanglong/dj/lib/python3.6/site-packages/redis/connection.py", line 489, in connect
    raise ConnectionError(self._error_message(e))
redis.exceptions.ConnectionError: Error 60 connecting to 10.211.55.5:6379. Operation timed out.

During handling of the above exception, another exception occurred:

Traceback (most recent call last):
  File "/Users/yinshuanglong/dj/lib/python3.6/site-packages/django/core/handlers/exception.py", line 41, in inner
    response = get_response(request)
  File "/Users/yinshuanglong/dj/lib/python3.6/site-packages/django/core/handlers/base.py", line 187, in _get_response
    response = self.process_exception_by_middleware(e, request)
  File "/Users/yinshuanglong/dj/lib/python3.6/site-packages/django/core/handlers/base.py", line 185, in _get_response
    response = wrapped_callback(request, *callback_args, **callback_kwargs)
  File "/Users/yinshuanglong/dj/lib/python3.6/site-packages/django/views/decorators/csrf.py", line 58, in wrapped_view
    return view_func(*args, **kwargs)
  File "/Users/yinshuanglong/dj/lib/python3.6/site-packages/django/views/generic/base.py", line 68, in view
    return self.dispatch(request, *args, **kwargs)
  File "/Users/yinshuanglong/dj/lib/python3.6/site-packages/rest_framework/views.py", line 495, in dispatch
    response = self.handle_exception(exc)
  File "/Users/yinshuanglong/dj/lib/python3.6/site-packages/rest_framework/views.py", line 452, in handle_exception
    response = exception_handler(exc, context)
  File "/Users/yinshuanglong/Desktop/mido/mido_mall/mido_mall/utils/exceptions.py", line 27, in exception_handler
    if isinstance(exc, DatabaseError) or isinstance(RedisError):
TypeError: isinstance expected 2 arguments, got 1
ERROR 2018-11-15 17:29:59,437 basehttp 124 "GET /sms_codes/15812341234/ HTTP/1.1" 500 152811
ERROR 2018-11-15 17:34:31,091 basehttp 124 "GET /sms_codes/15812341234/ HTTP/1.1" 507 30
INFO 2018-11-15 17:41:04,869 basehttp 124 "GET /sms_codes/15812341235/ HTTP/1.1" 200 16
INFO 2018-11-15 18:25:42,315 basehttp 124 "GET /sms_codes/15812341235/ HTTP/1.1" 200 16
INFO 2018-11-15 18:27:11,006 basehttp 124 "GET /sms_codes/15812341235/ HTTP/1.1" 200 16
INFO 2018-11-15 19:27:25,026 basehttp 124 "GET /sms_codes/15812341235/ HTTP/1.1" 200 16
WARNING 2018-11-15 19:27:25,233 tasks 22 发送验证码短信[失败][ mobile: 15812341235 ]
INFO 2018-11-15 19:59:25,920 basehttp 124 "GET /usernames/testuser1/count/ HTTP/1.1" 200 34
INFO 2018-11-15 20:01:49,184 basehttp 124 "GET /usernames/user1/count/ HTTP/1.1" 200 30
INFO 2018-11-15 20:05:58,238 basehttp 124 "GET /mobiles/15812341235/count/ HTTP/1.1" 200 34
INFO 2018-11-15 20:06:08,366 basehttp 124 "GET /mobiles/15812341234/count/ HTTP/1.1" 200 34
WARNING 2018-11-15 20:06:19,665 base 152 Not Found: /mobiles/1581234124/count/
WARNING 2018-11-15 20:06:19,669 basehttp 124 "GET /mobiles/1581234124/count/ HTTP/1.1" 404 2586
INFO 2018-11-15 20:06:25,673 basehttp 124 "GET /mobiles/15812341224/count/ HTTP/1.1" 200 34
INFO 2018-11-15 20:49:28,884 basehttp 124 "GET /sms_codes/15812341235/ HTTP/1.1" 200 16
WARNING 2018-11-15 20:49:29,142 tasks 22 发送验证码短信[失败][ mobile: 15812341235 ]
WARNING 2018-11-15 20:50:09,216 base 152 Not Found: /register.html
WARNING 2018-11-15 20:50:09,220 basehttp 124 "GET /register.html HTTP/1.1" 404 2710
WARNING 2018-11-15 20:50:10,176 base 152 Not Found: /favicon.ico
WARNING 2018-11-15 20:50:10,177 basehttp 124 "GET /favicon.ico HTTP/1.1" 404 2704
WARNING 2018-11-15 20:55:26,735 base 152 Not Found: /register.html
WARNING 2018-11-15 20:55:26,737 basehttp 124 "GET /register.html HTTP/1.1" 404 2710
WARNING 2018-11-15 20:56:42,317 base 152 Not Found: /register.html
WARNING 2018-11-15 20:56:42,321 basehttp 124 "GET /register.html HTTP/1.1" 404 2710
WARNING 2018-11-15 21:15:01,648 base 152 Not Found: /register.html
WARNING 2018-11-15 21:15:01,659 basehttp 124 "GET /register.html HTTP/1.1" 404 2710
INFO 2018-11-15 21:15:31,685 basehttp 124 "GET /sms_codes/15812341235/ HTTP/1.1" 200 16
INFO 2018-11-15 21:15:46,140 basehttp 124 "GET /sms_codes/15812341235/ HTTP/1.1" 200 16
WARNING 2018-11-15 21:18:10,662 base 152 Not Found: /register.html
WARNING 2018-11-15 21:18:10,664 basehttp 124 "GET /register.html HTTP/1.1" 404 2710
INFO 2018-11-15 21:34:22,837 basehttp 124 "GET /sms_codes/15812341235/ HTTP/1.1" 200 16
INFO 2018-11-15 21:42:57,067 basehttp 124 "GET /sms_codes/15812341235/ HTTP/1.1" 200 16
WARNING 2018-11-15 21:43:18,157 basehttp 124 "POST /users/ HTTP/1.1" 400 109
INFO 2018-11-15 21:43:37,655 basehttp 124 "GET /usernames/user1/count/ HTTP/1.1" 200 30
WARNING 2018-11-15 21:43:42,054 basehttp 124 "POST /users/ HTTP/1.1" 400 109
WARNING 2018-11-15 21:47:37,548 basehttp 124 "POST /users/ HTTP/1.1" 400 109
WARNING 2018-11-17 14:53:18,269 base 152 Not Found: /
WARNING 2018-11-17 14:53:18,273 basehttp 124 "GET / HTTP/1.1" 404 2649
WARNING 2018-11-17 14:53:18,780 base 152 Not Found: /favicon.ico
WARNING 2018-11-17 14:53:18,781 basehttp 124 "GET /favicon.ico HTTP/1.1" 404 2700
INFO 2018-11-17 15:06:03,666 basehttp 124 "GET /sms_codes/15812341235/ HTTP/1.1" 200 16
INFO 2018-11-17 16:01:59,442 basehttp 124 "GET /usernames/user1/count/ HTTP/1.1" 200 30
INFO 2018-11-17 16:02:09,858 basehttp 124 "GET /mobiles/15812341224/count/ HTTP/1.1" 200 34
INFO 2018-11-17 16:03:44,837 basehttp 124 "GET /mobiles/15812341235/count/ HTTP/1.1" 200 34
WARNING 2018-11-17 16:04:05,478 basehttp 124 "POST /users/ HTTP/1.1" 400 109
INFO 2018-11-17 16:04:14,777 basehttp 124 "GET /sms_codes/15812341235/ HTTP/1.1" 200 16
INFO 2018-11-17 16:07:31,537 basehttp 124 "GET /sms_codes/15812341235/ HTTP/1.1" 200 16
WARNING 2018-11-17 16:07:45,017 basehttp 124 "POST /users/ HTTP/1.1" 400 109
INFO 2018-11-17 16:09:25,886 basehttp 124 "GET /sms_codes/15812341235/ HTTP/1.1" 200 16
WARNING 2018-11-17 16:09:42,313 basehttp 124 "POST /users/ HTTP/1.1" 400 109
WARNING 2018-11-17 16:10:41,558 basehttp 124 "POST /users/ HTTP/1.1" 400 109
INFO 2018-11-17 16:10:48,280 basehttp 124 "GET /sms_codes/15812341235/ HTTP/1.1" 200 16
WARNING 2018-11-17 16:10:59,521 basehttp 124 "POST /users/ HTTP/1.1" 400 109
INFO 2018-11-17 16:18:26,168 basehttp 124 "GET /mobiles/15812341235/count/ HTTP/1.1" 200 34
INFO 2018-11-17 16:18:26,241 basehttp 124 "GET /mobiles/15812341235/count/ HTTP/1.1" 200 34
INFO 2018-11-17 16:19:43,726 basehttp 124 "GET /sms_codes/15812341235/ HTTP/1.1" 200 16
WARNING 2018-11-17 16:20:39,363 basehttp 124 "POST /users/ HTTP/1.1" 400 109
INFO 2018-11-17 16:21:17,125 basehttp 124 "OPTIONS /users/ HTTP/1.1" 200 0
INFO 2018-11-17 16:21:17,150 basehttp 124 "GET /usernames/user1/count/ HTTP/1.1" 200 30
INFO 2018-11-17 16:21:17,150 basehttp 124 "GET /mobiles/15812341235/count/ HTTP/1.1" 200 34
INFO 2018-11-17 16:21:17,367 basehttp 124 "POST /users/ HTTP/1.1" 201 50
INFO 2018-11-17 16:21:39,481 basehttp 124 "OPTIONS /authorizations/ HTTP/1.1" 200 0
WARNING 2018-11-17 16:21:39,491 base 152 Not Found: /authorizations/
WARNING 2018-11-17 16:21:39,492 basehttp 124 "POST /authorizations/ HTTP/1.1" 404 2717
WARNING 2018-11-17 16:21:41,980 base 152 Not Found: /authorizations/
WARNING 2018-11-17 16:21:41,981 basehttp 124 "POST /authorizations/ HTTP/1.1" 404 2717
WARNING 2018-11-17 16:21:49,798 base 152 Not Found: /authorizations/
WARNING 2018-11-17 16:21:49,798 basehttp 124 "POST /authorizations/ HTTP/1.1" 404 2717
WARNING 2018-11-17 16:21:50,679 base 152 Not Found: /authorizations/
WARNING 2018-11-17 16:21:50,679 basehttp 124 "POST /authorizations/ HTTP/1.1" 404 2717
WARNING 2018-11-17 16:21:58,087 base 152 Not Found: /authorizations/
WARNING 2018-11-17 16:21:58,087 basehttp 124 "POST /authorizations/ HTTP/1.1" 404 2717
WARNING 2018-11-17 16:21:59,917 base 152 Not Found: /authorizations/
WARNING 2018-11-17 16:21:59,917 basehttp 124 "POST /authorizations/ HTTP/1.1" 404 2717
WARNING 2018-11-17 16:22:06,074 base 152 Not Found: /authorizations/
WARNING 2018-11-17 16:22:06,075 basehttp 124 "POST /authorizations/ HTTP/1.1" 404 2717
INFO 2018-11-17 16:37:09,892 basehttp 124 "GET /sms_codes/15812341235/ HTTP/1.1" 200 16
WARNING 2018-11-17 16:37:25,244 basehttp 124 "POST /users/ HTTP/1.1" 400 109
INFO 2018-11-17 16:38:25,963 basehttp 124 "GET /sms_codes/15812341236/ HTTP/1.1" 200 16
WARNING 2018-11-17 16:38:42,213 basehttp 124 "POST /users/ HTTP/1.1" 400 109
INFO 2018-11-17 16:47:38,814 basehttp 124 "GET /usernames/user3/count/ HTTP/1.1" 200 30
INFO 2018-11-17 16:47:53,575 basehttp 124 "GET /mobiles/15812341239/count/ HTTP/1.1" 200 34
INFO 2018-11-17 16:47:53,587 basehttp 124 "GET /mobiles/15812341239/count/ HTTP/1.1" 200 34
INFO 2018-11-17 16:47:53,769 basehttp 124 "GET /sms_codes/15812341239/ HTTP/1.1" 200 16
INFO 2018-11-17 16:48:07,954 basehttp 124 "OPTIONS /users/ HTTP/1.1" 200 0
INFO 2018-11-17 16:48:07,982 basehttp 124 "GET /mobiles/15812341239/count/ HTTP/1.1" 200 34
INFO 2018-11-17 16:48:07,984 basehttp 124 "GET /usernames/user3/count/ HTTP/1.1" 200 30
INFO 2018-11-17 16:48:08,125 basehttp 124 "POST /users/ HTTP/1.1" 201 50
INFO 2018-11-17 16:49:12,279 basehttp 124 "GET /sms_codes/15812341239/ HTTP/1.1" 200 16
WARNING 2018-11-17 16:49:28,391 basehttp 124 "POST /users/ HTTP/1.1" 400 109
WARNING 2018-11-17 16:50:56,602 basehttp 124 "POST /users/ HTTP/1.1" 400 109
WARNING 2018-11-17 16:53:12,649 basehttp 124 "POST /users/ HTTP/1.1" 400 109
WARNING 2018-11-17 16:54:15,704 basehttp 124 "POST /users/ HTTP/1.1" 400 113
WARNING 2018-11-17 16:54:30,822 basehttp 124 "POST /users/ HTTP/1.1" 400 109
WARNING 2018-11-17 16:54:37,236 basehttp 124 "POST /users/ HTTP/1.1" 400 113
INFO 2018-11-17 17:25:17,133 basehttp 124 "GET /sms_codes/15812341240/ HTTP/1.1" 200 16
INFO 2018-11-17 17:25:35,285 basehttp 124 "POST /users/ HTTP/1.1" 201 222
WARNING 2018-11-17 17:32:25,443 basehttp 124 "POST /authorizations/ HTTP/1.1" 400 108
WARNING 2018-11-17 17:32:32,837 basehttp 124 "POST /authorizations/ HTTP/1.1" 400 67
